<?xml version="1.0" encoding="utf-8"?>
<!-- This URDF was automatically created by SolidWorks to URDF Exporter! Originally created by Stephen Brawner (brawner@gmail.com) 
     Commit Version: 1.6.0-1-g15f4949  Build Version: 1.6.7594.29634
     For more information, please see http://wiki.ros.org/sw_urdf_exporter -->
<robot
  name="description">

 
 <link name="base_footprint"/>

  <joint name="base_joint" type="fixed">
    <parent link="base_footprint"/>
    <child link="base_link"/>
    <origin xyz="0.0 0.0 0" rpy="0 0 -1.57"/>
  </joint>


  <link
    name="base_link">
    <inertial>
      <origin
        xyz="0.00604222427993528 0.0937383676015929 -0.0402106239401368"
        rpy="0 0 0" />
      <mass
        value="0.519076841043834" />
      <inertia
        ixx="0.00075109355134614"
        ixy="6.22413563458484E-10"
        ixz="-1.21335085888853E-08"
        iyy="0.00143705806630845"
        iyz="6.53873710779967E-07"
        izz="0.000714530468814509" />
    </inertial>
    <visual>
      <origin
        xyz="0 0 0"
        rpy="0 0 0" />
      <geometry>
        <mesh
          filename="package://description/meshes/base_link.STL" />
      </geometry>
      <material
        name="">
        <color
          rgba="0.792156862745098 0.819607843137255 0.933333333333333 1" />
      </material>
    </visual>
    <collision>
      <origin
        xyz="0 0 0"
        rpy="0 0 0" />
      <geometry>
        <mesh
          filename="package://description/meshes/base_link.STL" />
      </geometry>
    </collision>
  </link>
  <link
    name="imu_base">
    <inertial>
      <origin
        xyz="-0.0002247 -6.9389E-18 -0.0015"
        rpy="0 0 0" />
      <mass
        value="0.000942" />
      <inertia
        ixx="3.4363E-08"
        ixy="-5.1646E-25"
        ixz="-1.1114E-25"
        iyy="1.9247E-08"
        iyz="-6.1352E-24"
        izz="5.2197E-08" />
    </inertial>
    <visual>
      <origin
        xyz="0 0 0"
        rpy="0 0 0" />
      <geometry>
        <mesh
          filename="package://description/meshes/imu_link.STL" />
      </geometry>
      <material
        name="">
        <color
          rgba="1 0 0 1" />
      </material>
    </visual>
    <collision>
      <origin
        xyz="0 0 0"
        rpy="0 0 0" />
      <geometry>
        <mesh
          filename="package://description/meshes/imu_link.STL" />
      </geometry>
    </collision>
  </link>
  <joint
    name="imu_joint"
    type="fixed">
    <origin
      xyz="0.0063942 0.10863 0.040861"
      rpy="0 0 -1.5708" />
    <parent
      link="base_link" />
    <child
      link="imu_base" />
    <axis
      xyz="0 0 0" />
  </joint>
  <link
    name="caster_link">
    <inertial>
      <origin
        xyz="-1.38777878078145E-17 -6.93889390390723E-18 0.00620920157446308"
        rpy="0 0 0" />
      <mass
        value="0.00573786372737865" />
      <inertia
        ixx="3.01346626020544E-07"
        ixy="-3.30872245021211E-24"
        ixz="1.23097932257356E-23"
        iyy="3.01346626020544E-07"
        iyz="-1.4889642918021E-23"
        izz="4.48449911942938E-07" />
    </inertial>
    <visual>
      <origin
        xyz="0 0 0"
        rpy="0 0 0" />
      <geometry>
        <mesh
          filename="package://description/meshes/caster_link.STL" />
      </geometry>
      <material
        name="">
        <color
          rgba="0.792156862745098 0.819607843137255 0.933333333333333 1" />
      </material>
    </visual>
    <collision>
      <origin
        xyz="0 0 0"
        rpy="0 0 0" />
      <geometry>
        <mesh
          filename="package://description/meshes/caster_link.STL" />
      </geometry>
    </collision>
  </link>
  <joint
    name="caster_joint"
    type="fixed">
    <origin
      xyz="0 0.084145 -0.022819"
      rpy="1.5708 -0.16099 1.5708" />
    <parent
      link="base_link" />
    <child
      link="caster_link" />
    <axis
      xyz="0 0 0" />
  </joint>
  <link
    name="lidar_link">
    <inertial>
      <origin
        xyz="-8.6736E-19 1.3878E-17 -0.012944"
        rpy="0 0 0" />
      <mass
        value="0.090366" />
      <inertia
        ixx="2.9262E-05"
        ixy="7.1466E-37"
        ixz="3.7542E-22"
        iyy="2.9262E-05"
        iyz="3.4542E-21"
        izz="4.6984E-05" />
    </inertial>
    <visual>
      <origin
        xyz="0 0 0"
        rpy="0 0 0" />
      <geometry>
        <mesh
          filename="package://description/meshes/lidar_link.STL" />
      </geometry>
      <material
        name="">
        <color
          rgba="0 0 1 1" />
      </material>
    </visual>
    <collision>
      <origin
        xyz="0 0 0"
        rpy="0 0 0" />
      <geometry>
        <mesh
          filename="package://description/meshes/lidar_link.STL" />
      </geometry>
    </collision>
  </link>
  <joint
    name="lidar_joint"
    type="fixed">
    <origin
      xyz="0.0042092 0.080995 0.1932"
      rpy="3.14 -3.14 1.57" />
    <parent
      link="base_link" />
    <child
      link="lidar_link" />
    <axis
      xyz="0 0 0" />
  </joint>
  <link
    name="wheel_R_link">
    <inertial>
      <origin
        xyz="-0.016617 -8.7963E-12 -7.3698E-07"
        rpy="0 0 0" />
      <mass
        value="0.053158" />
      <inertia
        ixx="4.0958E-05"
        ixy="3.054E-15"
        ixz="2.443E-10"
        iyy="2.3293E-05"
        iyz="5.1359E-16"
        izz="2.3293E-05" />
    </inertial>
    <visual>
      <origin
        xyz="0 0 0"
        rpy="0 0 0" />
      <geometry>
        <mesh
          filename="package://description/meshes/wheel_R_link.STL" />
      </geometry>
      <material
        name="">
        <color
          rgba="0 0 0 1" />
      </material>
    </visual>
    <collision>
      <origin
        xyz="0 0 0"
        rpy="0 0 0" />
      <geometry>
        <mesh
          filename="package://description/meshes/wheel_R_link.STL" />
      </geometry>
    </collision>
  </link>
  <joint
    name="wheel_R_joint"
    type="continuous">
    <origin
      xyz="0.073109 0.001672 -0.0015622"
      rpy="1.5708 0 3.1416" />
    <parent
      link="base_link" />
    <child
      link="wheel_R_link" />
    <axis
      xyz="1 0 0" />
  </joint>
  <link
    name="wheel_L_link">
    <inertial>
      <origin
        xyz="0 0 0"
        rpy="0 0 0" />
      <mass
        value="0" />
      <inertia
        ixx="0"
        ixy="0"
        ixz="0"
        iyy="0"
        iyz="0"
        izz="0" />
    </inertial>
    <visual>
      <origin
        xyz="0 0 0"
        rpy="0 0 0" />
      <geometry>
        <mesh
          filename="package://description/meshes/wheel_L_link.STL" />
      </geometry>
      <material
        name="">
        <color
          rgba="0 0 0 1" />
      </material>
    </visual>
    <collision>
      <origin
        xyz="0 0 0"
        rpy="0 0 0" />
      <geometry>
        <mesh
          filename="package://description/meshes/wheel_L_link.STL" />
      </geometry>
    </collision>
  </link>
  <joint
    name="wheel_L_joint"
    type="continuous">
    <origin
      xyz="-0.060691 0.001672 -0.0015622"
      rpy="1.5708 0 0" />
    <parent
      link="base_link" />
    <child
      link="wheel_L_link" />
    <axis
      xyz="1 0 0" />
  </joint>


 <link name="usb_cam"/>

  <joint name="cam_joint" type="fixed">
    <parent link="lidar_link"/>
    <child link="usb_cam"/>
    <origin xyz="0.0 0.0 0" rpy="0 0 0"/>
  </joint>


</robot>